#VRML_SIM R2023b utf8

EXTERNPROTO "https://raw.githubusercontent.com/cyberbotics/webots/R2023b/projects/objects/backgrounds/protos/TexturedBackground.proto"
EXTERNPROTO "https://raw.githubusercontent.com/cyberbotics/webots/R2023b/projects/objects/backgrounds/protos/TexturedBackgroundLight.proto"
EXTERNPROTO "https://raw.githubusercontent.com/cyberbotics/webots/R2023b/projects/objects/floors/protos/RectangleArena.proto"

WorldInfo {
  info [
    "Example use of a color Camera device."
  ]
  title "Camera"
}
Viewpoint {
  orientation 0.008813916483997881 -0.999953797645644 0.0038363329192719585 5.556183314478952
  position -1.0187672728877113 0.09686604036180091 1.0949116244793602
}
TexturedBackground {
}
TexturedBackgroundLight {
}
RectangleArena {
}
PointLight {
  attenuation 0 0 1
  intensity 0.6
  location 0 0 0.6
}
DEF GREEN_BOX Solid {
  translation 0.25 0.05 0.05
  children [
    Shape {
      appearance PBRAppearance {
        baseColor 0 1 0
        roughness 0.2189099510000001
        metalness 0
      }
      geometry DEF BOX0 Box {
        size 0.1 0.23 0.1
      }
    }
  ]
  name "green box"
  boundingObject Shape {
    appearance PBRAppearance {
      metalness 0
    }
    geometry USE BOX0
  }
}
DEF BLUE_BOX Solid {
  translation -0.27 -0.2 0.05
  rotation 0 0 1 0.31
  children [
    Shape {
      appearance PBRAppearance {
        baseColor 0 0 1
        roughness 0.519341125
        metalness 0
      }
      geometry DEF BOX1 Box {
        size 0.1 0.2 0.1
      }
    }
  ]
  name "blue box"
  boundingObject Shape {
    appearance PBRAppearance {
      metalness 0
    }
    geometry USE BOX1
  }
}
DEF WHITE_BOX Solid {
  translation -0.15 0.2 0.05
  rotation 0 0 1 0.4
  children [
    Shape {
      appearance PBRAppearance {
        baseColor 0.74902 0.74902 0.74902
        roughness 0.10196099999999997
        metalness 0
      }
      geometry DEF BOX2 Box {
        size 0.3 0.05 0.1
      }
    }
  ]
  name "gray box"
  boundingObject Shape {
    appearance PBRAppearance {
      metalness 0
    }
    geometry USE BOX2
  }
}
DEF RED_BOX Solid {
  translation 0.1 -0.42 0.05
  rotation 0 0 1 1.8326
  children [
    Shape {
      appearance PBRAppearance {
        baseColor 1 0 0
        roughness 0.16827074099999995
        metalness 0
      }
      geometry DEF BOX3 Box {
        size 0.08 0.2 0.1
      }
    }
  ]
  name "red box"
  boundingObject Shape {
    appearance PBRAppearance {
      metalness 0
    }
    geometry USE BOX3
  }
}
Robot {
  translation -0.002715059189517785 -0.1500930886462879 -0.00032949888735218924
  rotation -0.013361455322731166 0.001212365318051887 0.9999099967907081 2.9615568906277163
  children [
    Pose {
      translation 0 0 0.0415
      rotation 0 0 1 -1.570796
      children [
        Shape {
          appearance PBRAppearance {
            baseColor 0.0820075 0.364731 0.8
            roughness 1
            metalness 0
          }
          geometry DEF BODY Cylinder {
            height 0.08
            radius 0.045
          }
        }
      ]
    }
    HingeJoint {
      jointParameters HingeJointParameters {
        position -26.067542524750138
        axis 0 1 0
        anchor 0 0 0.025
      }
      device [
        RotationalMotor {
          name "left wheel motor"
          consumptionFactor 70
        }
        PositionSensor {
          name "left wheel sensor"
        }
      ]
      endPoint Solid {
        translation 0 0.045 0.025
        rotation 0.49360131160804915 -0.4936014146522099 -0.716041471307459 1.898770150297118
        children [
          DEF WHEEL Pose {
            rotation 0.577656895078166 0.5771968951617173 -0.5771968951617173 -2.093935
            children [
              Shape {
                appearance PBRAppearance {
                  baseColor 1 0 0
                  roughness 1
                  metalness 0
                }
                geometry Cylinder {
                  height 0.01
                  radius 0.025
                }
              }
            ]
          }
        ]
        name "left wheel"
        boundingObject USE WHEEL
        physics DEF PHYSICS_WHEEL Physics {
          density -1
          mass 0.05
        }
        linearVelocity -7.149433222142712e-05 0.001237222072808801 -1.967216367944486e-05
        angularVelocity -0.04846643651858777 -0.0051723426768204555 -0.013688848312983616
      }
    }
    HingeJoint {
      jointParameters HingeJointParameters {
        position 26.06771010914212
        axis 0 1 0
        anchor 0 0 0.025
      }
      device [
        RotationalMotor {
          name "right wheel motor"
          consumptionFactor 70
        }
        PositionSensor {
          name "right wheel sensor"
        }
      ]
      endPoint Solid {
        translation 0 -0.045000000000000005 0.025
        rotation -0.4511620944616981 0.4511620587043703 -0.7700036112295632 1.8292307723943697
        children [
          USE WHEEL
        ]
        name "right wheel"
        boundingObject USE WHEEL
        physics USE PHYSICS_WHEEL
        linearVelocity -0.0006008837573061787 -0.0020181023032938106 -1.87524127689186e-05
        angularVelocity 0.04338234033566817 -0.02176056989434799 -0.013191305023189211
      }
    }
    DistanceSensor {
      translation 0.042 0.02 0.063
      rotation 0 0 -1 -0.499205
      children [
        DEF SENSOR Pose {
          rotation 0.577656895078166 0.5771968951617173 -0.5771968951617173 -2.093935
          children [
            Shape {
              appearance PBRAppearance {
                baseColor 0.975691 0.981481 0.0252992
                roughness 1
                metalness 0
              }
              geometry Cylinder {
                height 0.004
                radius 0.008
              }
            }
          ]
        }
      ]
      name "ds0"
      lookupTable [
        0 1024 0
        0.05 1024 0
        0.15 0 0
      ]
      numberOfRays 2
      aperture 1
    }
    DistanceSensor {
      translation 0.042 -0.02 0.063
      rotation 0 0 1 -0.500795
      children [
        USE SENSOR
      ]
      name "ds1"
      lookupTable [
        0 1024 0
        0.05 1024 0
        0.15 0 0
      ]
      numberOfRays 2
      aperture 1
    }
    DEF SMILE Pose {
      translation 0.036 0 0.025
      rotation 0.25056300542381216 -0.9351130202419243 -0.25056300542381216 1.637834
      children [
        Shape {
          appearance PBRAppearance {
            baseColor 0.721569 0.290196 0.290196
            roughness 1
            metalness 0
          }
          geometry Cylinder {
            height 0.018
            radius 0.009
            subdivision 3
          }
        }
      ]
    }
    Camera {
      translation 0.04 0 0.0915
      children [
        Pose {
          translation -0.015 0 0
          rotation -0.5771968951617173 -0.577656895078166 -0.5771968951617173 -2.093935
          children [
            Shape {
              appearance PBRAppearance {
                roughness 1
                metalness 0
              }
              geometry Cylinder {
                height 0.03
                radius 0.01
              }
            }
          ]
        }
      ]
      fieldOfView 1.047
      width 80
      height 60
      antiAliasing TRUE
      noise 0.04
    }
  ]
  name "MyBot"
  boundingObject Pose {
    translation 0 0 0.0415
    rotation 0 0 1 -1.570796
    children [
      USE BODY
    ]
  }
  physics Physics {
    density -1
    mass 0.5
  }
  controller "camera"
  linearVelocity -0.0005354725917475695 -0.0003397966291504985 0.0007909633506531569
  angularVelocity -0.002399897533837494 -0.013492538481366676 -0.04299851004507817
}
